Workbook

Sheet 集計
A1: 版ごとのコスト集計
A3: 版 | B3: タスク数 | C3: 完了数 | D3: 未見積 | E3: 見積コスト | F3: 実コスト | G3: 完了分の見積 | H3: 進捗率 | I3: 見積と実績の差
A4: プロト | B4: =COUNTIF(タスク一覧!$E$2:$E$116,$A4) -> 63 | C4: =COUNTIFS(タスク一覧!$E$2:$E$116,$A4,タスク一覧!$G$2:$G$116,"完了") -> 49 | D4: =SUMPRODUCT((タスク一覧!$E$2:$E$116=$A4)*(タスク一覧!$H$2:$H$116=0)) -> 0 | E4: =SUMIF(タスク一覧!$E$2:$E$116,$A4,タスク一覧!$H$2:$H$116) -> 144.5 | F4: =SUMIF(タスク一覧!$E$2:$E$116,$A4,タスク一覧!$I$2:$I$116) -> 0 | G4: =SUMIFS(タスク一覧!$H$2:$H$116,タスク一覧!$E$2:$E$116,$A4,タスク一覧!$G$2:$G$116,"完了") -> 111.5 | H4: =IFERROR(G4/E4,0) -> 0.7716263 | I4: =SUMIFS(タスク一覧!$I$2:$I$116,タスク一覧!$E$2:$E$116,$A4,タスク一覧!$G$2:$G$116,"完了")-G4 -> -111.5
A5: アルファ | B5: =COUNTIF(タスク一覧!$E$2:$E$116,$A5) -> 31 | C5: =COUNTIFS(タスク一覧!$E$2:$E$116,$A5,タスク一覧!$G$2:$G$116,"完了") -> 2 | D5: =SUMPRODUCT((タスク一覧!$E$2:$E$116=$A5)*(タスク一覧!$H$2:$H$116=0)) -> 0 | E5: =SUMIF(タスク一覧!$E$2:$E$116,$A5,タスク一覧!$H$2:$H$116) -> 64 | F5: =SUMIF(タスク一覧!$E$2:$E$116,$A5,タスク一覧!$I$2:$I$116) -> 0 | G5: =SUMIFS(タスク一覧!$H$2:$H$116,タスク一覧!$E$2:$E$116,$A5,タスク一覧!$G$2:$G$116,"完了") -> 2 | H5: =IFERROR(G5/E5,0) -> 0.03125 | I5: =SUMIFS(タスク一覧!$I$2:$I$116,タスク一覧!$E$2:$E$116,$A5,タスク一覧!$G$2:$G$116,"完了")-G5 -> -2
A6: ベータ | B6: =COUNTIF(タスク一覧!$E$2:$E$116,$A6) -> 20 | C6: =COUNTIFS(タスク一覧!$E$2:$E$116,$A6,タスク一覧!$G$2:$G$116,"完了") -> 1 | D6: =SUMPRODUCT((タスク一覧!$E$2:$E$116=$A6)*(タスク一覧!$H$2:$H$116=0)) -> 0 | E6: =SUMIF(タスク一覧!$E$2:$E$116,$A6,タスク一覧!$H$2:$H$116) -> 62 | F6: =SUMIF(タスク一覧!$E$2:$E$116,$A6,タスク一覧!$I$2:$I$116) -> 0 | G6: =SUMIFS(タスク一覧!$H$2:$H$116,タスク一覧!$E$2:$E$116,$A6,タスク一覧!$G$2:$G$116,"完了") -> 1 | H6: =IFERROR(G6/E6,0) -> 0.016129032 | I6: =SUMIFS(タスク一覧!$I$2:$I$116,タスク一覧!$E$2:$E$116,$A6,タスク一覧!$G$2:$G$116,"完了")-G6 -> -1
A7: マスタ | B7: =COUNTIF(タスク一覧!$E$2:$E$116,$A7) -> 1 | C7: =COUNTIFS(タスク一覧!$E$2:$E$116,$A7,タスク一覧!$G$2:$G$116,"完了") -> 0 | D7: =SUMPRODUCT((タスク一覧!$E$2:$E$116=$A7)*(タスク一覧!$H$2:$H$116=0)) -> 0 | E7: =SUMIF(タスク一覧!$E$2:$E$116,$A7,タスク一覧!$H$2:$H$116) -> 1 | F7: =SUMIF(タスク一覧!$E$2:$E$116,$A7,タスク一覧!$I$2:$I$116) -> 0 | G7: =SUMIFS(タスク一覧!$H$2:$H$116,タスク一覧!$E$2:$E$116,$A7,タスク一覧!$G$2:$G$116,"完了") -> 0 | H7: =IFERROR(G7/E7,0) -> 0 | I7: =SUMIFS(タスク一覧!$I$2:$I$116,タスク一覧!$E$2:$E$116,$A7,タスク一覧!$G$2:$G$116,"完了")-G7 -> 0
A8: 合計 | B8: =SUM(B4:B7) -> 115 | C8: =SUM(C4:C7) -> 52 | D8: =SUM(D4:D7) -> 0 | E8: =SUM(E4:E7) -> 271.5 | F8: =SUM(F4:F7) -> 0 | G8: =SUM(G4:G7) -> 114.5 | H8: =IFERROR(G8/E8,0) -> 0.42173112 | I8: =SUM(I4:I7) -> -114.5
A10: 進捗率 = 状態が「完了」のタスクの見積コスト ÷ 見積コスト合計。見積と実績の差 = 完了タスクの実コスト − その見積コスト（プラス = 見積より多くかかった）。

Sheet カレンダー
A1: 開発カレンダー
A3: 版 | B3: 開始 | C3: 終了 | D3: 日数 | E3: 作業可能時間 | F3: 見積時間 | G3: 余裕
A4: プロト | B4: 46296 | C4: 46326 | D4: =C4-B4+1 -> 31 | E4: =D4*設定!$B$6 -> 248 | F4: =SUMIF(タスク一覧!$E:$E,A4,タスク一覧!$H:$H)*設定!$B$5 -> 144.5 | G4: =E4-F4 -> 103.5 | I4: 青字の開始・終了日を変えると、下のカレンダーの色も自動で変わります。
A5: アルファ | B5: 46327 | C5: 46356 | D5: =C5-B5+1 -> 30 | E5: =D5*設定!$B$6 -> 240 | F5: =SUMIF(タスク一覧!$E:$E,A5,タスク一覧!$H:$H)*設定!$B$5 -> 64 | G5: =E5-F5 -> 176 | I5: 作業可能時間 = 日数 × 1日の作業時間（設定シート）。土日も作業日として数えています。
A6: ベータ | B6: 46357 | C6: 46379 | D6: =C6-B6+1 -> 23 | E6: =D6*設定!$B$6 -> 184 | F6: =SUMIF(タスク一覧!$E:$E,A6,タスク一覧!$H:$H)*設定!$B$5 -> 62 | G6: =E6-F6 -> 122
A7: マスタ | B7: 46380 | C7: 46386 | D7: =C7-B7+1 -> 7 | E7: =D7*設定!$B$6 -> 56 | F7: =SUMIF(タスク一覧!$E:$E,A7,タスク一覧!$H:$H)*設定!$B$5 -> 1 | G7: =E7-F7 -> 55
A10: 2026 年 10 月 | I10: 2026 年 11 月 | Q10: 2026 年 12 月
A11: 日 | B11: 月 | C11: 火 | D11: 水 | E11: 木 | F11: 金 | G11: 土 | I11: 日 | J11: 月 | K11: 火 | L11: 水 | M11: 木 | N11: 金 | O11: 土 | Q11: 日 | R11: 月 | S11: 火 | T11: 水 | U11: 木 | V11: 金 | W11: 土
E12: 46296 | F12: 46297 | G12: 46298 | I12: 46327 | J12: 46328 | K12: 46329 | L12: 46330 | M12: 46331 | N12: 46332 | O12: 46333 | S12: 46357 | T12: 46358 | U12: 46359 | V12: 46360 | W12: 46361
A13: 46299 | B13: 46300 | C13: 46301 | D13: 46302 | E13: 46303 | F13: 46304 | G13: 46305 | I13: 46334 | J13: 46335 | K13: 46336 | L13: 46337 | M13: 46338 | N13: 46339 | O13: 46340 | Q13: 46362 | R13: 46363 | S13: 46364 | T13: 46365 | U13: 46366 | V13: 46367 | W13: 46368
A14: 46306 | B14: 46307 | C14: 46308 | D14: 46309 | E14: 46310 | F14: 46311 | G14: 46312 | I14: 46341 | J14: 46342 | K14: 46343 | L14: 46344 | M14: 46345 | N14: 46346 | O14: 46347 | Q14: 46369 | R14: 46370 | S14: 46371 | T14: 46372 | U14: 46373 | V14: 46374 | W14: 46375
A15: 46313 | B15: 46314 | C15: 46315 | D15: 46316 | E15: 46317 | F15: 46318 | G15: 46319 | I15: 46348 | J15: 46349 | K15: 46350 | L15: 46351 | M15: 46352 | N15: 46353 | O15: 46354 | Q15: 46376 | R15: 46377 | S15: 46378 | T15: 46379 | U15: 46380 | V15: 46381 | W15: 46382
A16: 46320 | B16: 46321 | C16: 46322 | D16: 46323 | E16: 46324 | F16: 46325 | G16: 46326 | I16: 46355 | J16: 46356 | Q16: 46383 | R16: 46384 | S16: 46385 | T16: 46386 | U16: 46387
A19: 色なし = どの版の期間にも入っていない日

Sheet タスク一覧
A1: 分類1 | B1: 分類2 | C1: 分類3 | D1: タスク | E1: 版 | F1: 優先度 | G1: 状態 | H1: 見積コスト | I1: 実コスト | J1: メモ
A2: プレイヤー | B2: 移動 | D2: カメラ基準の歩き・走り | E2: プロト | F2: A | G2: 完了 | H2: 0.5
A3: プレイヤー | B3: 移動 | D3: 旋回・加速・減速 | E3: プロト | F3: A | G3: 進行中 | H3: 3
A4: プレイヤー | B4: ジャンプ | D4: 通常ジャンプ | E4: プロト | F4: A | G4: 完了 | H4: 0.5
A5: プレイヤー | B5: ジャンプ | D5: 2段ジャンプ | E5: プロト | F5: A | G5: 未着手 | H5: 0.5
A6: プレイヤー | B6: ジャンプ | D6: 落下・着地硬直 | E6: プロト | F6: B | G6: 未着手 | H6: 0.5
A7: プレイヤー | B7: 回避 | D7: 地上回避 | E7: プロト | F7: A | G7: 完了 | H7: 0.5
A8: プレイヤー | B8: 回避 | D8: 空中回避 | E8: プロト | F8: A | G8: 未着手 | H8: 0.5
A9: プレイヤー | B9: 回避 | D9: 無敵時間・連続回避の制限 | E9: プロト | F9: A | G9: 進行中 | H9: 0.5
A10: プレイヤー | B10: ジャスト回避 | D10: 判定の時間 | E10: プロト | F10: A | G10: 完了 | H10: 0.5
A11: プレイヤー | B11: ジャスト回避 | D11: 成功でウィッチタイム発動 | E11: プロト | F11: A | G11: 完了 | H11: 0.5
A12: プレイヤー | B12: 被弾 | D12: 怯み・吹っ飛び・起き上がり | E12: プロト | F12: A | G12: 進行中 | H12: 5
A13: プレイヤー | B13: 被弾 | D13: 被弾後の無敵時間 | E13: プロト | F13: A | G13: 完了 | H13: 0.5
... A34: 攻撃 | B34: 銃 | D34: 攻撃中・空中で撃つ | E34: プロト | F34: A | G34: 完了 | H34: 4
A35: 攻撃 | B35: でかい手 | D35: 発生タイミング・当たり判定 | E35: プロト | F35: A | G35: 完了 | H35: 3 | J35: ウィケッドウィーブ
A36: 攻撃 | B36: でかい手 | D36: 演出 | E36: プロト | F36: A | G36: 完了 | H36: 2
A37: ウィッチタイム | B37: 時間 | D37: 敵・弾・エフェクトだけスロー | E37: プロト | F37: A | G37: 進行中 | H37: 3 | J37: プレイヤーは通常の速さ
A38: ウィッチタイム | B38: 時間 | D38: 継続時間・終わり方 | E38: プロト | F38: A | G38: 進行中 | H38: 3
A39: ウィッチタイム | B39: 演出 | D39: 画面の色・開始演出 | E39: プロト | F39: A | G39: 進行中 | H39: 3
A40: 当たり判定 | B40: 攻撃 | D40: アニメのフレームに合わせて出し消し | E40: プロト | F40: A | G40: 完了 | H40: 2
A41: 当たり判定 | B41: 攻撃 | D41: 多段ヒット防止 | E41: プロト | F41: A | G41: 完了 | H41: 2
A42: 当たり判定 | B42: 被弾 | D42: キャラごとの形と大きさ | E42: プロト | F42: A | G42: 完了 | H42: 2
A43: 当たり判定 | B43: 押し合い | D43: プレイヤーと敵・敵同士 | E43: プロト | F43: A | G43: 完了 | H43: 2
A44: 当たり判定 | B44: 地形 | D44: 壁・床へのめり込み・段差 | E44: プロト | F44: A | G44: 完了 | H44: 2
A45: 当たり判定 | B45: 弾 | D45: 弾とキャラ・弾と地形 | E45: プロト | F45: B | G45: 進行中 | H45: 3
A46: カメラ | B46: 通常 | D46: 追従 | E46: プロト | F46: A | G46: 完了 | H46: 0.5
A47: カメラ | B47: 通常 | D47: 右スティックの手動操作 | E47: プロト | F47: A | G47: 完了 | H47: 0.5
A48: カメラ | B48: ロックオン | D48: ロックオン中の画角 | E48: プロト | F48: A | G48: 未着手 | H48: 3
A49: カメラ | B49: 地形 | D49: 壁へのめり込み対策 | E49: プロト | F49: A | G49: 完了 | H49: 2
A50: カメラ | B50: 演出 | D50: 一時的なカメラ切り替え | E50: アルファ | F50: A | G50: 未着手 | H50: 3 | J50: ボス登場・とどめなど
A51: Enemy | B51: 共通 | D51: 被弾・怯み | E51: プロト | F51: A | G51: 完了 | H51: 5
A52: Enemy | B52: 共通 | D52: 吹っ飛び・打ち上げ・ダウン・起き上がり | E52: プロト | F52: A | G52: 完了 | H52: 10 | J52: タイムスケールとか重力を考えると吹っ飛び難しい(打ち上げの空中感はアルファでやる)
A53: Enemy | B53: 共通 | D53: 死亡ステート・消え方 | E53: プロト | F53: A | G53: 完了 | H53: 2 | J53: Alien.cppにTODOあり
A54: Enemy | B54: 共通 | D54: 攻撃の予兆（光る） | E54: プロト | F54: A | G54: 完了 | H54: 1 | J54: ジャスト回避の合図
A55: Enemy | B55: 共通 | D55: 追跡・攻撃の選び方 | E55: プロト | F55: A | G55: 完了 | H55: 3
A56: Enemy | B56: 共通 | D56: 同時に攻撃してくる数の制限 | E56: アルファ | F56: A | G56: 未着手 | H56: 2
A57: Enemy | B57: 共通 | D57: ウィッチタイム中のスロー | E57: プロト | F57: A | G57: 完了 | H57: 0.5
A58: Enemy | B58: 共通 | D58: ステータスのデータ読み込み | E58: プロト | F58: A | G58: 完了 | H58: 0.5
A59: Enemy | B59: 共通 | D59: 出現・ウェーブ管理 | E59: アルファ | F59: A | G59: 未着手 | H59: 2
A60: Enemy | B60: エイリアン | D60: 攻撃パターン | E60: プロト | F60: A | G60: 完了 | H60: 3
...

Sheet 設定
A1: WinterGame2026 設定
A3: 開始日 | B3: 46282
A4: 締切 | B4: 46386
A5: 1コストあたり時間 | B5: 1
A6: 1日の作業時間 | B6: 8
A7: 残り日数（今日から締切） | B7: =MAX(0,B4-TODAY()) -> 62
A8: 期間全体の作業可能時間 | B8: =(B4-B3+1)*B6 -> 840
A10: 青字のセルは編集できます。値は WinterGame2026.json（board-planner）から取り込んだものです。

Sheet memo
A2: 1022
B3: デカイ手の演出終わらせる
B4: エイリアンの挙動も完成させる
B5: 竜巻を豪鬼の大竜にする
A9: 1024
B10: エイリアンの仕様
B11: 浮遊している
B12: 遠距離攻撃をする(ブレス攻撃)
B13: 踵落としで叩き落せる
B14: デカイ手の攻撃でも落とせる
B15: 攻撃したあとプレイヤーから距離をとって様子をみる
B16: 攻撃の予兆がある
A18: 1029
B19: カメラのロックオン
B20: マップを作る
B21: スポーン条件作る
B22: ボスの設計やる
